2018-06-21 14:30:08,198 ERROR: Exception on /predictmany [POST] [in /usr/local/lib/python3.5/dist-packages/flask/app.py:1761]
Traceback (most recent call last):
  File "/usr/local/lib/python3.5/dist-packages/flask/app.py", line 2292, in wsgi_app
    response = self.full_dispatch_request()
  File "/usr/local/lib/python3.5/dist-packages/flask/app.py", line 1815, in full_dispatch_request
    rv = self.handle_user_exception(e)
  File "/usr/local/lib/python3.5/dist-packages/flask/app.py", line 1718, in handle_user_exception
    reraise(exc_type, exc_value, tb)
  File "/usr/local/lib/python3.5/dist-packages/flask/_compat.py", line 35, in reraise
    raise value
  File "/usr/local/lib/python3.5/dist-packages/flask/app.py", line 1813, in full_dispatch_request
    rv = self.dispatch_request()
  File "/usr/local/lib/python3.5/dist-packages/flask/app.py", line 1799, in dispatch_request
    return self.view_functions[rule.endpoint](**req.view_args)
  File "/home/victorl/Documents/DIPLOMADO-UPEL-EducacionUniversitaria/TEMAS-o-AREAS/COMPUTER-SCIENCE/EJEMPLOS/PYTHON/FLASK/sentimentpredictor/webapp/restapi/routes.py", line 16, in predictmany
    predictions,prediction_labels=model.get_predicttions(test_df['comment'])
AttributeError: 'Mlmodel' object has no attribute 'get_predicttions'
2018-06-21 14:30:33,608 INFO: ML RESTAPI startup [in /home/victorl/Documents/DIPLOMADO-UPEL-EducacionUniversitaria/TEMAS-o-AREAS/COMPUTER-SCIENCE/EJEMPLOS/PYTHON/FLASK/sentimentpredictor/webapp/__init__.py:38]
2018-06-21 14:30:36,437 ERROR: Exception on /predictmany [POST] [in /usr/local/lib/python3.5/dist-packages/flask/app.py:1761]
Traceback (most recent call last):
  File "/usr/local/lib/python3.5/dist-packages/flask/app.py", line 2292, in wsgi_app
    response = self.full_dispatch_request()
  File "/usr/local/lib/python3.5/dist-packages/flask/app.py", line 1816, in full_dispatch_request
    return self.finalize_request(rv)
  File "/usr/local/lib/python3.5/dist-packages/flask/app.py", line 1831, in finalize_request
    response = self.make_response(rv)
  File "/usr/local/lib/python3.5/dist-packages/flask/app.py", line 1957, in make_response
    'The view function did not return a valid response. The'
TypeError: The view function did not return a valid response. The function either returned None or ended without a return statement.
2018-06-21 14:31:13,260 INFO: ML RESTAPI startup [in /home/victorl/Documents/DIPLOMADO-UPEL-EducacionUniversitaria/TEMAS-o-AREAS/COMPUTER-SCIENCE/EJEMPLOS/PYTHON/FLASK/sentimentpredictor/webapp/__init__.py:38]
2018-06-21 14:32:51,283 INFO: ML RESTAPI startup [in /home/victorl/Documents/DIPLOMADO-UPEL-EducacionUniversitaria/TEMAS-o-AREAS/COMPUTER-SCIENCE/EJEMPLOS/PYTHON/FLASK/sentimentpredictor/webapp/__init__.py:38]
2018-06-23 07:32:57,297 INFO: ML RESTAPI startup [in /home/victorl/Documents/DIPLOMADO-UPEL-EducacionUniversitaria/TEMAS-o-AREAS/COMPUTER-SCIENCE/EJEMPLOS/PYTHON/FLASK/sentimentpredictor/webapp/__init__.py:38]
2018-06-23 07:37:50,863 INFO: ML RESTAPI startup [in /home/victorl/Documents/DIPLOMADO-UPEL-EducacionUniversitaria/TEMAS-o-AREAS/COMPUTER-SCIENCE/EJEMPLOS/PYTHON/FLASK/sentimentpredictor/webapp/__init__.py:38]
2018-07-18 14:08:04,209 INFO: ML RESTAPI startup [in /home/victorl/Documents/DIPLOMADO-UPEL-EducacionUniversitaria/TEMAS-o-AREAS/COMPUTER-SCIENCE/EJEMPLOS/PYTHON/FLASK/sentimentpredictor/webapp/__init__.py:38]
